Workbook

Sheet 개요
A1: 개인 업무 세분화 — Unity 클라이언트 개발자
A3: 과제 | B3: AI 에이전트 강의 과제 2: 개인 업무 세분화
A4: 작성일 | B4: 2026-10-05
A5: 직무 | B5: Unity 클라이언트 개발자 (키글 스튜디오)
A6: 팀 구성 | B6: 프로젝트 1개당 클라이언트 1 · 기획 1 · 사운드 1. 프로젝트의 Unity 업무는 본인 1인 전담
A7: 사용 도구 | B7: Unity, GitLab, Slack, 스프레드시트(팀 스케줄 공유표, 피드백 시트, 사운드 키 시트, 다국어 시트)
A9: 시트 구성
A10: 업무분해 | B10: 업무 1건 = 1행. 대분류 → 중분류 → 세부 작업 3단계, 단계·시간 단위·소요 시간·AI 활용 가능성 포함 (원본 데이터)
A11: 프로젝트흐름 | B11: 팀 진행도 표 기준 프로젝트 단계 순서와 단계별 개발자 업무 (업무 ID로 연결)
A12: 시간단위별 | B12: 일간 / 주간 / 프로젝트 단계별 / 비정기로 묶어 본 업무 목록 (업무분해 시트를 참조)
A13: 요약분석 | B13: 대분류·시간 단위·AI 활용 가능성별 작업 수와 월 소요 시간 (수식으로 자동 집계)
A14: AI활용후보 | B14: AI 에이전트로 자동화·보조할 업무 우선순위와 구체적인 방법
A16: 분류 기준
A17: 시간 단위 | B17: 일간: 거의 매일 / 주간: 주 1회 이상 / 프로젝트 단계별: 해당 단계에서 반복 / 비정기: 프로젝트당 1회 또는 이슈 발생 시
A18: 반복성 | B18: 상: 같은 절차를 자주 반복 / 중: 절차는 비슷하나 내용이 매번 다름 / 하: 매번 판단이 필요
A19: AI 활용 가능성 | B19: 상: 입력·출력이 명확해 자동화 가능 / 중: 초안·보조로 시간 단축 / 하: 사람 판단·실물 확인이 핵심
A20: 불편 업무 ★ | B20: 본인이 직접 '시간을 잡아먹는 일'로 지목한 업무
A22: 범례
A23: 노란 칸 · 파란 글자 | B23: 추정값(월 빈도, 회당 소요 시간)입니다. 실제 값으로 고치면 '월 소요(h)'와 요약분석이 자동으로 다시 계산됩니다
A24: 빨간 행 | B24: 불편 업무 ★

Sheet 업무분해
A1: ID | B1: 대분류 | C1: 중분류 | D1: 세부 작업 | E1: 프로젝트 단계 | F1: 시간 단위 | G1: 월 빈도(회) | H1: 회당 소요(h) | I1: 월 소요(h) | J1: 입력(받는 것) | K1: 산출물 | L1: 도구 | M1: 협업 대상 | N1: 반복성 | O1: 불편 업무 | P1: AI 활용 가능성 | Q1: AI 활용 아이디어
A2: A-01 | B2: 프로젝트 관리 | C2: 일정 관리 | D2: 킥오프 후 개발 단계별 일정을 팀 스케줄 공유표에 작성 | E2: 기획(러프·킥오프) | F2: 프로젝트 단계별 | G2: 0.25 | H2: 2 | I2: =G2*H2 | J2: 기획서, 킥오프 결정사항 | K2: 팀 스케줄 공유표 | L2: 스프레드시트 | M2: 기획 | N2: 중 | P2: 중 | Q2: 기획서 기반 작업 목록 → 일정 초안 자동 생성
A3: A-02 | B3: 프로젝트 관리 | C3: 일정 관리 | D3: 개발자 업무 진행도(단계별 셀) 갱신 | E3: 상시 | F3: 주간 | G3: 4 | H3: 0.5 | I3: =G3*H3 | J3: 이번 주 작업 결과 | K3: 진행도 시트 갱신 | L3: 스프레드시트 | M3: 기획 | N3: 상 | P3: 상 | Q3: GitLab 커밋 기록으로 진행 상황 요약 → 시트 갱신 초안
A4: A-03 | B4: 프로젝트 관리 | C4: 회의 | D4: 주간회의 준비 (지난주 한 일 / 이번 주 할 일 정리) | E4: 상시 | F4: 주간 | G4: 4 | H4: 0.5 | I4: =G4*H4 | J4: 커밋 기록, Slack 대화 | K4: 회의 공유 내용 | L4: Slack, GitLab | M4: 팀 전체 | N4: 상 | P4: 상 | Q4: 최근 7일 git log 요약으로 주간 보고 초안 작성
A5: A-04 | B5: 프로젝트 관리 | C5: 회의 | D5: 주간회의 참석 (월요일) | E5: 상시 | F5: 주간 | G5: 4 | H5: 1 | I5: =G5*H5 | J5: 회의 안건 | K5: 결정사항 메모 | L5: - | M5: 팀 전체 | N5: 상 | P5: 하 | Q5: 회의 메모 → 할 일 목록으로 정리 (회의 참석 자체는 대체 불가)
A6: A-05 | B6: 프로젝트 관리 | C6: 회의 | D6: 러프 전달 회의: 기획 러프 검토, 구현 가능성·리스크 의견 | E6: 기획(러프·킥오프) | F6: 프로젝트 단계별 | G6: 0.25 | H6: 1.5 | I6: =G6*H6 | J6: 기획 러프 | K6: 구현 가능성 의견 | L6: - | M6: 기획, 사운드 | N6: 하 | P6: 중 | Q6: 러프 문서를 읽고 기술 리스크·필요 리소스 체크리스트 초안
A7: A-06 | B7: 프로젝트 관리 | C7: 회의 | D7: 킥오프: 범위·일정 확정 | E7: 기획(러프·킥오프) | F7: 프로젝트 단계별 | G7: 0.25 | H7: 1.5 | I7: =G7*H7 | J7: 확정 기획서 | K7: 확정 범위·일정 | L7: - | M7: 기획, 사운드 | N7: 하 | P7: 하 | Q7: -
A8: A-07 | B8: 프로젝트 관리 | C8: 기획 분석 | D8: 기획서를 구현 단위 작업 목록으로 분해 | E8: 기획(러프·킥오프) | F8: 프로젝트 단계별 | G8: 0.25 | H8: 4 | I8: =G8*H8 | J8: 기획서 | K8: 구현 작업 목록 | L8: 스프레드시트 | M8: 기획 | N8: 중 | P8: 상 | Q8: 기획서 → 기능/화면/연출/사운드 단위 작업 리스트 자동 분해
A9: B-01 | B9: 프로젝트 셋업 | C9: 신규 프로젝트 | D9: Unity 프로젝트 생성, 버전·플랫폼·Player Settings(번들ID 등) 설정 | E9: 셋업 | F9: 비정기 | G9: 0.25 | H9: 3 | I9: =G9*H9 | J9: 프로젝트 정보 | K9: 초기 프로젝트 | L9: Unity | M9: - | N9: 중 | P9: 상 | Q9: Editor 스크립트로 공통 설정 일괄 적용 + 체크리스트
A10: B-02 | B10: 프로젝트 셋업 | C10: 신규 프로젝트 | D10: GitLab 저장소 생성, .gitignore·LFS·브랜치 규칙 세팅 | E10: 셋업 | F10: 비정기 | G10: 0.25 | H10: 1 | I10: =G10*H10 | J10: - | K10: 원격 저장소 | L10: GitLab | M10: - | N10: 중 | P10: 상 | Q10: 저장소 초기화 스크립트화
A11: B-03 | B11: 프로젝트 셋업 | C11: 신규 프로젝트 | D11: 공통 모듈·SDK(광고/결제/분석 등) import 및 설정 | E11: 셋업 | F11: 비정기 | G11: 0.25 | H11: 4 | I11: =G11*H11 | J11: 공통 패키지 | K11: SDK 연동 완료 | L11: Unity | M11: - | N11: 중 | P11: 중 | Q11: SDK 버전·설정 누락 점검 체크리스트
A12: B-04 | B12: 프로젝트 셋업 | C12: 신규 프로젝트 | D12: 폴더 구조·기본 씬·공통 프리팹 템플릿 세팅 | E12: 셋업 | F12: 비정기 | G12: 0.25 | H12: 2 | I12: =G12*H12 | J12: 사내 템플릿 | K12: 기본 구조 | L12: Unity | M12: - | N12: 중 | P12: 상 | Q12: 템플릿 프로젝트 복제 + 이름 일괄 변경 자동화
A13: C-01 | B13: 개발 구현 | C13: 기능 개발 | D13: 게임 로직·기능 스크립트 작성 | E13: 개발 구현 | F13: 일간 | G13: 20 | H13: 2 | I13: =G13*H13 | J13: 기획서, 작업 목록 | K13: 기능 코드 | L13: Unity, GitLab | M13: 기획 | N13: 중 | P13: 중 | Q13: Claude Code로 반복 코드·보일러플레이트 작성, 버그 원인 탐색
... A20: D-02 | B20: 피드백·QA | C20: 피드백 적용 | D20: 피드백 수정 작업 | E20: QA | F20: 일간 | G20: 15 | H20: 1 | I20: =G20*H20 | J20: 피드백 항목 | K20: 수정 코드 | L20: Unity, GitLab | M20: 기획 | N20: 상 | P20: 중 | Q20: 피드백 문장 → 관련 스크립트 위치 찾기·수정안 제시
A21: D-03 | B21: 피드백·QA | C21: 피드백 적용 확인 | D21: 피드백 항목별 반영 여부 확인 및 시트 상태 갱신 | E21: QA | F21: 일간 | G21: 15 | H21: 0.5 | I21: =G21*H21 | J21: 피드백 시트, 커밋 기록 | K21: 상태 갱신된 시트 | L21: 스프레드시트, GitLab | M21: 기획 | N21: 상 | O21: ★ | P21: 상 | Q21: 피드백 ID ↔ 커밋 매칭으로 미반영 목록 자동 추출
A22: D-04 | B22: 피드백·QA | C22: QA 대응 | D22: 기획QA 이슈 수정 | E22: QA | F22: 프로젝트 단계별 | G22: 0.25 | H22: 8 | I22: =G22*H22 | J22: 기획QA 리스트 | K22: 수정 빌드 | L22: Unity | M22: 기획 | N22: 중 | P22: 중 | Q22: 이슈 목록 우선순위 분류, 원인 코드 탐색
A23: D-05 | B23: 피드백·QA | C23: QA 대응 | D23: 컨썸QA 이슈 수정 | E23: QA | F23: 프로젝트 단계별 | G23: 0.25 | H23: 8 | I23: =G23*H23 | J23: 컨썸QA 리스트 | K23: 수정 빌드 | L23: Unity | M23: 기획 | N23: 중 | P23: 중 | Q23: 이슈 목록 우선순위 분류, 원인 코드 탐색
A24: D-06 | B24: 피드백·QA | C24: QA 대응 | D24: 기능QA 버그 수정 | E24: QA | F24: 프로젝트 단계별 | G24: 0.25 | H24: 12 | I24: =G24*H24 | J24: 기능QA 리스트 | K24: 수정 빌드 | L24: Unity | M24: 기획 | N24: 중 | P24: 중 | Q24: 버그 리포트 → 재현 단계·원인 후보 정리
A25: D-07 | B25: 피드백·QA | C25: 버그 분석 | D25: 버그 재현 및 원인 분석 | E25: QA | F25: 비정기 | G25: 6 | H25: 1 | I25: =G25*H25 | J25: 버그 리포트, 로그 | K25: 원인 파악 | L25: Unity | M25: 기획 | N25: 중 | P25: 상 | Q25: Unity 콘솔/에러 로그 분석으로 원인 후보 제시
A26: E-01 | B26: 사운드 연동 | C26: 리소스 | D26: 사운드 담당자가 전달한 파일 import·설정 | E26: 개발 구현 | F26: 프로젝트 단계별 | G26: 2 | H26: 1 | I26: =G26*H26 | J26: 사운드 파일 | K26: import된 AudioClip | L26: Unity, Slack | M26: 사운드 | N26: 상 | P26: 상 | Q26: 파일명 규칙 검사 + import 설정 일괄 적용
A27: E-02 | B27: 사운드 연동 | C27: 키 연동 | D27: 스프레드시트 사운드 키를 코드/테이블에 연결 | E27: 개발 구현 | F27: 프로젝트 단계별 | G27: 2 | H27: 2 | I27: =G27*H27 | J27: 사운드 키 시트 | K27: 사운드 테이블 | L27: Unity, 스프레드시트 | M27: 사운드 | N27: 상 | P27: 상 | Q27: 시트 → 사운드 테이블 자동 생성
A28: E-03 | B28: 사운드 연동 | C28: 적용 확인 | D28: 시트의 사운드 키가 정상 재생되는지 Unity 로그로 확인 | E28: 개발 구현 | F28: 프로젝트 단계별 | G28: 2 | H28: 2 | I28: =G28*H28 | J28: 사운드 키 시트, Unity 로그 | K28: 확인 결과 | L28: Unity, 스프레드시트 | M28: 사운드 | N28: 상 | O28: ★ | P28: 상 | Q28: 시트 키 목록 ↔ Unity 로그 자동 대조 → 누락·오타·미재생 리포트
A29: E-04 | B29: 사운드 연동 | C29: 조정 | D29: 볼륨·재생 타이밍 조정 | E29: 개발 구현 | F29: 프로젝트 단계별 | G29: 2 | H29: 1 | I29: =G29*H29 | J29: 사운드 피드백 | K29: 조정 완료 | L29: Unity | M29: 사운드 | N29: 중 | P29: 하 | Q29: -
A30: F-01 | B30: 빌드·배포 | C30: 테스트 빌드 | D30: Android/iOS 테스트 빌드 생성 | E30: 개발 구현 | F30: 주간 | G30: 6 | H30: 1 | I30: =G30*H30 | J30: 최신 코드 | K30: 테스트 빌드 | L30: Unity | M30: - | N30: 상 | P30: 상 | Q30: 빌드 스크립트 + GitLab CI 자동 빌드
A31: F-02 | B31: 빌드·배포 | C31: 배포 공지 | D31: 테스트 빌드 배포 및 Slack 공유 (링크·변경사항) | E31: 개발 구현 | F31: 주간 | G31: 6 | H31: 0.5 | I31: =G31*H31 | J31: 테스트 빌드, 커밋 기록 | K31: 배포 공지 | L31: Slack, GitLab | M31: 기획, 사운드 | N31: 상 | P31: 상 | Q31: 지난 빌드 이후 커밋 요약 → 공지문 자동 작성
A32: F-03 | B32: 빌드·배포 | C32: 빌드 오류 | D32: 빌드 실패·플랫폼별 오류 대응 | E32: 개발 구현 | F32: 비정기 | G32: 2 | H32: 1 | I32: =G32*H32 | J32: 빌드 로그 | K32: 해결 | L32: Unity | M32: - | N32: 중 | P32: 상 | Q32: 빌드 로그 분석으로 원인·해결책 제시
A33: F-04 | B33: 빌드·배포 | C33: 버전 관리 | D33: 커밋·브랜치·태그, 버전코드 관리 | E33: 상시 | F33: 일간 | G33: 20 | H33: 0.25 | I33: =G33*H33 | J33: 작업 내용 | K33: 커밋 | L33: GitLab | M33: - | N33: 상 | P33: 중 | Q33: 커밋 메시지 자동 작성, 버전코드 자동 증가
A34: G-01 | B34: 다국어 | C34: 텍스트 반영 | D34: 다국어 텍스트 시트 → 프로젝트 반영 | E34: 다국어 | F34: 프로젝트 단계별 | G34: 0.5 | H34: 2 | I34: =G34*H34 | J34: 다국어 시트 | K34: 로컬라이징 데이터 | L34: 스프레드시트, Unity | M34: 기획 | N34: 상 | P34: 상 | Q34: 시트 → 데이터 변환, 누락 키·포맷 오류 검사
A35: G-02 | B35: 다국어 | C35: UI 확인 | D35: 언어별 UI 깨짐 확인 (폰트, 글자 넘침) | E35: 다국어 | F35: 프로젝트 단계별 | G35: 0.5 | H35: 2 | I35: =G35*H35 | J35: 다국어 빌드 | K35: 확인 결과 | L35: Unity | M35: 기획 | N35: 중 | P35: 중 | Q35: 언어별 글자수 초과 후보 사전 검출
A36: G-03 | B36: 다국어 | C36: 리소스 교체 | D36: 언어별 이미지·폰트 리소스 교체 | E36: 다국어 | F36: 프로젝트 단계별 | G36: 0.5 | H36: 1 | I36: =G36*H36 | J36: 언어별 리소스 | K36: 교체 완료 | L36: Unity | M36: 기획 | N36: 중 | P36: 중 | Q36: 리소스 누락 검사 스크립트
A37: H-01 | B37: 출시·스토어 | C37: 스토어 개설 | D37: Google Play Console / App Store Connect 앱 등록 | E37: 출시 준비 | F37: 비정기 | G37: 0.25 | H37: 2 | I37: =G37*H37 | J37: 앱 정보 | K37: 스토어 페이지 | L37: 스토어 콘솔 | M37: 기획 | N37: 하 | P37: 하 | Q37: 등록 항목 체크리스트 제공 (입력은 직접)
A38: H-02 | B38: 출시·스토어 | C38: 스토어 정보 | D38: 설명·스크린샷·연령등급·개인정보 항목 작성 | E38: 출시 준비 | F38: 비정기 | G38: 0.25 | H38: 3 | I38: =G38*H38 | J38: 기획 자료 | K38: 스토어 정보 | L38: 스토어 콘솔 | M38: 기획 | N38: 하 | P38: 중 | Q38: 다국어 스토어 설명문 초안, 키즈 정책 체크리스트
A39: H-03 | B39: 출시·스토어 | C39: 출시 빌드 | D39: 릴리즈 빌드(서명·설정) 생성 | E39: 출시 준비 | F39: 비정기 | G39: 0.25 | H39: 2 | I39: =G39*H39 | J39: 최종 코드 | K39: 릴리즈 빌드 | L39: Unity | M39: - | N39: 중 | P39: 상 | Q39: 출시 전 설정 점검 스크립트 (디버그 로그 제거 등)
A40: H-04 | B40: 출시·스토어 | C40: 심사 | D40: 심사 제출 및 리젝 대응 | E40: 출시 준비 | F40: 비정기 | G40: 0.25 | H40: 2 | I40: =G40*H40 | J40: 심사 결과 | K40: 출시 | L40: 스토어 콘솔 | M40: 기획 | N40: 하 | P40: 중 | Q40: 리젝 사유 해석·대응 방안 정리
... A45: J-02 | B45: 커뮤니케이션 | C45: 요청 | D45: 리소스·사운드 요청 및 전달 사항 정리 | E45: 상시 | F45: 비정기 | G45: 4 | H45: 0.3 | I45: =G45*H45 | J45: 작업 필요사항 | K45: 요청 메시지 | L45: Slack | M45: 기획, 사운드 | N45: 중 | P45: 중 | Q45: 필요 리소스 목록 → 요청 메시지 초안

Sheet 프로젝트흐름
A1: 순서 | B1: 단계 | C1: 시점·기간 | D1: 개발자 주요 작업 | E1: 관련 업무 ID | F1: 완료 조건·산출물
A2: 1 | B2: 러프 전달 회의 | C2: 프로젝트 시작 | D2: 기획 러프 검토, 구현 가능성·리스크 의견 | E2: A-05 | F2: 구현 방향 공유
A3: 2 | B3: 킥오프 | C3: 러프 확정 후 | D3: 범위·일정 확정, 기획서 작업 분해, 팀 스케줄 공유표 작성 | E3: A-06, A-07, A-01 | F3: 확정 일정표
A4: 3 | B4: 준비 기간 | C4: 킥오프 후 1개월+ 텀 | D4: 신규 프로젝트 세팅(Unity·GitLab·SDK·템플릿) | E4: B-01 ~ B-04 | F4: 개발 가능한 프로젝트 골격
A5: 4 | B5: 개발 구현 | C5: 준비 기간 이후 | D5: 기능·컨텐츠 개발, 연출, 파티클, 사운드 연동, 밸런싱(초안), 테스트 빌드 배포 | E5: C-01 ~ C-06, E-01 ~ E-04, F-01 ~ F-03 | F5: 기능 완성 빌드
A6: 5 | B6: 기획QA | C6: 개발 완료 후 | D6: 기획 의도대로 구현됐는지 검수, 이슈 수정 | E6: D-01 ~ D-04 | F6: 기획QA 통과
A7: 6 | B7: 컨썸QA | C7: 기획QA 이후 | D7: 컨썸QA 이슈 수정 | E7: D-05 | F7: 컨썸QA 통과
A8: 7 | B8: 기능QA | C8: 컨썸QA 이후 | D8: 버그·기능 검수 대응, 버그 수정 | E8: D-06, D-07 | F8: 기능QA 통과
A9: 8 | B9: 다국어 업데이트 | C9: QA 이후 | D9: 다국어 텍스트·리소스 반영, 언어별 UI 확인 | E9: G-01 ~ G-03 | F9: 다국어 빌드
A10: 9 | B10: 출시 준비 | C10: 다국어 이후 (확인 필요) | D10: 스토어 개설·정보 작성, 릴리즈 빌드, 심사 대응 | E10: H-01 ~ H-04 | F10: 스토어 출시
A11: 10 | B11: 코드 정리 | C11: 출시 전후 | D11: 미사용 코드·에셋 정리, 리팩토링 | E11: I-01 | F11: 정리된 코드
A12: 11 | B12: 유지보수 | C12: 지속 | D12: Unity·SDK 버전 업, 출시 후 이슈 대응 | E12: I-02, I-03 | F12: 안정 운영
A14: ※ 단계 1~8, 10, 11은 팀 '개발자 업무 진행도' 표 기준. 9 출시 준비는 표에 보이지 않아 위치를 추정했습니다. 실제 순서에 맞게 고쳐 주세요.

Sheet 시간단위별
A1: 시간 단위 | B1: ID | C1: 대분류 | D1: 세부 작업 | E1: 월 소요(h) | F1: AI 활용 가능성
A2: 일간 | B2: =업무분해!A13 | C2: =업무분해!B13 | D2: =업무분해!D13 | E2: =업무분해!I13 | F2: =업무분해!P13
A3: 일간 | B3: =업무분해!A14 | C3: =업무분해!B14 | D3: =업무분해!D14 | E3: =업무분해!I14 | F3: =업무분해!P14
A4: 일간 | B4: =업무분해!A15 | C4: =업무분해!B15 | D4: =업무분해!D15 | E4: =업무분해!I15 | F4: =업무분해!P15
A5: 일간 | B5: =업무분해!A16 | C5: =업무분해!B16 | D5: =업무분해!D16 | E5: =업무분해!I16 | F5: =업무분해!P16
A6: 일간 | B6: =업무분해!A19 | C6: =업무분해!B19 | D6: =업무분해!D19 | E6: =업무분해!I19 | F6: =업무분해!P19
A7: 일간 | B7: =업무분해!A20 | C7: =업무분해!B20 | D7: =업무분해!D20 | E7: =업무분해!I20 | F7: =업무분해!P20
A8: 일간 | B8: =업무분해!A21 | C8: =업무분해!B21 | D8: =업무분해!D21 | E8: =업무분해!I21 | F8: =업무분해!P21
A9: 일간 | B9: =업무분해!A33 | C9: =업무분해!B33 | D9: =업무분해!D33 | E9: =업무분해!I33 | F9: =업무분해!P33
A10: 일간 | B10: =업무분해!A44 | C10: =업무분해!B44 | D10: =업무분해!D44 | E10: =업무분해!I44 | F10: =업무분해!P44
D11: 일간 소계 | E11: =SUMIF(A2:A10,"일간",E2:E10)
A12: 주간 | B12: =업무분해!A3 | C12: =업무분해!B3 | D12: =업무분해!D3 | E12: =업무분해!I3 | F12: =업무분해!P3
A13: 주간 | B13: =업무분해!A4 | C13: =업무분해!B4 | D13: =업무분해!D4 | E13: =업무분해!I4 | F13: =업무분해!P4
A14: 주간 | B14: =업무분해!A5 | C14: =업무분해!B5 | D14: =업무분해!D5 | E14: =업무분해!I5 | F14: =업무분해!P5
A15: 주간 | B15: =업무분해!A30 | C15: =업무분해!B30 | D15: =업무분해!D30 | E15: =업무분해!I30 | F15: =업무분해!P30
A16: 주간 | B16: =업무분해!A31 | C16: =업무분해!B31 | D16: =업무분해!D31 | E16: =업무분해!I31 | F16: =업무분해!P31
D17: 주간 소계 | E17: =SUMIF(A2:A16,"주간",E2:E16)
A18: 프로젝트 단계별 | B18: =업무분해!A2 | C18: =업무분해!B2 | D18: =업무분해!D2 | E18: =업무분해!I2 | F18: =업무분해!P2
A19: 프로젝트 단계별 | B19: =업무분해!A6 | C19: =업무분해!B6 | D19: =업무분해!D6 | E19: =업무분해!I6 | F19: =업무분해!P6
A20: 프로젝트 단계별 | B20: =업무분해!A7 | C20: =업무분해!B7 | D20: =업무분해!D7 | E20: =업무분해!I7 | F20: =업무분해!P7
A21: 프로젝트 단계별 | B21: =업무분해!A8 | C21: =업무분해!B8 | D21: =업무분해!D8 | E21: =업무분해!I8 | F21: =업무분해!P8
A22: 프로젝트 단계별 | B22: =업무분해!A17 | C22: =업무분해!B17 | D22: =업무분해!D17 | E22: =업무분해!I17 | F22: =업무분해!P17
A23: 프로젝트 단계별 | B23: =업무분해!A22 | C23: =업무분해!B22 | D23: =업무분해!D22 | E23: =업무분해!I22 | F23: =업무분해!P22
A24: 프로젝트 단계별 | B24: =업무분해!A23 | C24: =업무분해!B23 | D24: =업무분해!D23 | E24: =업무분해!I23 | F24: =업무분해!P23
A25: 프로젝트 단계별 | B25: =업무분해!A24 | C25: =업무분해!B24 | D25: =업무분해!D24 | E25: =업무분해!I24 | F25: =업무분해!P24
A26: 프로젝트 단계별 | B26: =업무분해!A26 | C26: =업무분해!B26 | D26: =업무분해!D26 | E26: =업무분해!I26 | F26: =업무분해!P26
A27: 프로젝트 단계별 | B27: =업무분해!A27 | C27: =업무분해!B27 | D27: =업무분해!D27 | E27: =업무분해!I27 | F27: =업무분해!P27
A28: 프로젝트 단계별 | B28: =업무분해!A28 | C28: =업무분해!B28 | D28: =업무분해!D28 | E28: =업무분해!I28 | F28: =업무분해!P28
A29: 프로젝트 단계별 | B29: =업무분해!A29 | C29: =업무분해!B29 | D29: =업무분해!D29 | E29: =업무분해!I29 | F29: =업무분해!P29
A30: 프로젝트 단계별 | B30: =업무분해!A34 | C30: =업무분해!B34 | D30: =업무분해!D34 | E30: =업무분해!I34 | F30: =업무분해!P34
A31: 프로젝트 단계별 | B31: =업무분해!A35 | C31: =업무분해!B35 | D31: =업무분해!D35 | E31: =업무분해!I35 | F31: =업무분해!P35
A32: 프로젝트 단계별 | B32: =업무분해!A36 | C32: =업무분해!B36 | D32: =업무분해!D36 | E32: =업무분해!I36 | F32: =업무분해!P36
A33: 프로젝트 단계별 | B33: =업무분해!A41 | C33: =업무분해!B41 | D33: =업무분해!D41 | E33: =업무분해!I41 | F33: =업무분해!P41
D34: 프로젝트 단계별 소계 | E34: =SUMIF(A2:A33,"프로젝트 단계별",E2:E33)
A35: 비정기 | B35: =업무분해!A9 | C35: =업무분해!B9 | D35: =업무분해!D9 | E35: =업무분해!I9 | F35: =업무분해!P9
A36: 비정기 | B36: =업무분해!A10 | C36: =업무분해!B10 | D36: =업무분해!D10 | E36: =업무분해!I10 | F36: =업무분해!P10
A37: 비정기 | B37: =업무분해!A11 | C37: =업무분해!B11 | D37: =업무분해!D11 | E37: =업무분해!I11 | F37: =업무분해!P11
A38: 비정기 | B38: =업무분해!A12 | C38: =업무분해!B12 | D38: =업무분해!D12 | E38: =업무분해!I12 | F38: =업무분해!P12
A39: 비정기 | B39: =업무분해!A18 | C39: =업무분해!B18 | D39: =업무분해!D18 | E39: =업무분해!I18 | F39: =업무분해!P18
A40: 비정기 | B40: =업무분해!A25 | C40: =업무분해!B25 | D40: =업무분해!D25 | E40: =업무분해!I25 | F40: =업무분해!P25
...

Sheet 요약분석
A1: 업무 요약 (업무분해 시트 기준 자동 집계)
A3: 전체 월 소요(h) | B3: =SUM(업무분해!I2:I45) | C3: 전체 작업 수 | D3: =COUNTA(업무분해!A2:A45)
A6: 대분류별 업무
A7: 대분류별 | B7: 작업 수 | C7: 월 소요(h) | D7: 시간 비중
A8: 프로젝트 관리 | B8: =COUNTIF(업무분해!$B$2:$B$45,A8) | C8: =SUMIF(업무분해!$B$2:$B$45,A8,업무분해!$I$2:$I$45) | D8: =IFERROR(C8/$B$3,0)
A9: 프로젝트 셋업 | B9: =COUNTIF(업무분해!$B$2:$B$45,A9) | C9: =SUMIF(업무분해!$B$2:$B$45,A9,업무분해!$I$2:$I$45) | D9: =IFERROR(C9/$B$3,0)
A10: 개발 구현 | B10: =COUNTIF(업무분해!$B$2:$B$45,A10) | C10: =SUMIF(업무분해!$B$2:$B$45,A10,업무분해!$I$2:$I$45) | D10: =IFERROR(C10/$B$3,0)
A11: 피드백·QA | B11: =COUNTIF(업무분해!$B$2:$B$45,A11) | C11: =SUMIF(업무분해!$B$2:$B$45,A11,업무분해!$I$2:$I$45) | D11: =IFERROR(C11/$B$3,0)
A12: 사운드 연동 | B12: =COUNTIF(업무분해!$B$2:$B$45,A12) | C12: =SUMIF(업무분해!$B$2:$B$45,A12,업무분해!$I$2:$I$45) | D12: =IFERROR(C12/$B$3,0)
A13: 빌드·배포 | B13: =COUNTIF(업무분해!$B$2:$B$45,A13) | C13: =SUMIF(업무분해!$B$2:$B$45,A13,업무분해!$I$2:$I$45) | D13: =IFERROR(C13/$B$3,0)
A14: 다국어 | B14: =COUNTIF(업무분해!$B$2:$B$45,A14) | C14: =SUMIF(업무분해!$B$2:$B$45,A14,업무분해!$I$2:$I$45) | D14: =IFERROR(C14/$B$3,0)
A15: 출시·스토어 | B15: =COUNTIF(업무분해!$B$2:$B$45,A15) | C15: =SUMIF(업무분해!$B$2:$B$45,A15,업무분해!$I$2:$I$45) | D15: =IFERROR(C15/$B$3,0)
A16: 유지보수 | B16: =COUNTIF(업무분해!$B$2:$B$45,A16) | C16: =SUMIF(업무분해!$B$2:$B$45,A16,업무분해!$I$2:$I$45) | D16: =IFERROR(C16/$B$3,0)
A17: 커뮤니케이션 | B17: =COUNTIF(업무분해!$B$2:$B$45,A17) | C17: =SUMIF(업무분해!$B$2:$B$45,A17,업무분해!$I$2:$I$45) | D17: =IFERROR(C17/$B$3,0)
A18: 합계 | B18: =SUM(B8:B17) | C18: =SUM(C8:C17) | D18: =SUM(D8:D17)
A20: 시간단위별 업무
A21: 시간단위별 | B21: 작업 수 | C21: 월 소요(h) | D21: 시간 비중
A22: 일간 | B22: =COUNTIF(업무분해!$F$2:$F$45,A22) | C22: =SUMIF(업무분해!$F$2:$F$45,A22,업무분해!$I$2:$I$45) | D22: =IFERROR(C22/$B$3,0)
A23: 주간 | B23: =COUNTIF(업무분해!$F$2:$F$45,A23) | C23: =SUMIF(업무분해!$F$2:$F$45,A23,업무분해!$I$2:$I$45) | D23: =IFERROR(C23/$B$3,0)
A24: 프로젝트 단계별 | B24: =COUNTIF(업무분해!$F$2:$F$45,A24) | C24: =SUMIF(업무분해!$F$2:$F$45,A24,업무분해!$I$2:$I$45) | D24: =IFERROR(C24/$B$3,0)
A25: 비정기 | B25: =COUNTIF(업무분해!$F$2:$F$45,A25) | C25: =SUMIF(업무분해!$F$2:$F$45,A25,업무분해!$I$2:$I$45) | D25: =IFERROR(C25/$B$3,0)
A26: 합계 | B26: =SUM(B22:B25) | C26: =SUM(C22:C25) | D26: =SUM(D22:D25)
A28: AI활용가능성별 업무
A29: AI활용가능성별 | B29: 작업 수 | C29: 월 소요(h) | D29: 시간 비중
A30: 상 | B30: =COUNTIF(업무분해!$P$2:$P$45,A30) | C30: =SUMIF(업무분해!$P$2:$P$45,A30,업무분해!$I$2:$I$45) | D30: =IFERROR(C30/$B$3,0)
A31: 중 | B31: =COUNTIF(업무분해!$P$2:$P$45,A31) | C31: =SUMIF(업무분해!$P$2:$P$45,A31,업무분해!$I$2:$I$45) | D31: =IFERROR(C31/$B$3,0)
A32: 하 | B32: =COUNTIF(업무분해!$P$2:$P$45,A32) | C32: =SUMIF(업무분해!$P$2:$P$45,A32,업무분해!$I$2:$I$45) | D32: =IFERROR(C32/$B$3,0)
A33: 합계 | B33: =SUM(B30:B32) | C33: =SUM(C30:C32) | D33: =SUM(D30:D32)
A35: 불편 업무 ★ 월 소요(h) | C35: =SUMIF(업무분해!O2:O45,"★",업무분해!I2:I45)
A37: ※ 월 소요 시간은 '업무분해' 시트의 노란 칸(추정값)으로 계산합니다. 실제 값으로 고치면 자동으로 다시 계산됩니다.

Sheet AI활용후보
A1: 순위 | B1: 업무 ID | C1: 업무 | D1: 지금 방식 | E1: AI가 해줄 수 있는 것 | F1: 필요한 재료·연결 | G1: 난이도 | H1: 기대 효과 | I1: 바로 해볼 첫 단계
A2: 1 | B2: E-03 | C2: 사운드 키 적용 확인 ★ | D2: 사운드 키 시트를 보며 Unity에서 직접 재생하고 로그를 눈으로 대조 | E2: ① 시트 키 목록과 Unity 로그를 자동 대조해 '로그에 안 찍힌 키 / 오타 / 중복 / AudioClip 없음' 리포트 작성 ② 모든 키를 차례로 재생하는 Editor 테스트 스크립트 작성 ③ Unity MCP로 Claude가 콘솔 로그를 직접 읽음 (이미 설치되어 있음) | F2: 사운드 키 시트(CSV 내보내기), Unity 로그(Editor.log 또는 Unity MCP), 사운드 재생 코드 | G2: 하 | H2: 확인 시간 대폭 단축, 누락 방지 | I2: 로그 형식을 '[Sound] Play: 키이름'으로 통일 → 시트 CSV와 로그를 Claude에 주고 대조 요청
A3: 2 | B3: D-03 | C3: 피드백 적용 확인 ★ | D3: 피드백 시트 항목을 하나씩 보며 반영됐는지 직접 확인하고 상태 갱신 | E3: ① 피드백 ID와 GitLab 커밋 메시지·diff를 매칭해 '반영됨 / 미반영 / 확인 필요' 목록 자동 생성 ② 시트 상태 컬럼 갱신안 작성 | F3: 피드백 시트, GitLab 커밋 기록, 커밋 메시지에 피드백 ID를 넣는 규칙 | G3: 중 | H3: 반영 누락 방지, 확인 시간 단축 | I3: 커밋 메시지에 피드백 번호를 넣기 시작 (예: 'FB-12 버튼 위치 수정') → 주 1회 대조 요청
A4: 3 | B4: D-01, D-02 | C4: 피드백 정리·수정 | D4: Slack·시트에 흩어진 피드백을 직접 읽고 관련 코드를 찾아 수정 | E4: ① 흩어진 피드백을 표로 정리하고 중복 제거 ② 피드백 문장으로 관련 스크립트·프리팹 위치를 찾아 수정안 제시 (Claude Code) | F4: Slack 메시지, 피드백 시트, Unity 프로젝트 폴더 | G4: 중 | H4: 수정 착수 시간 단축 | I4: 피드백 1건을 Claude Code에 붙여넣고 '관련 코드 찾아서 수정안 보여줘' 시도
A5: 4 | B5: F-02, F-01 | C5: 테스트 빌드 배포 공지 | D5: 빌드 후 변경사항을 직접 정리해 Slack에 공유 | E5: ① 지난 빌드 이후 커밋 기록을 요약해 공지문 자동 작성 ② 나중에는 GitLab CI 자동 빌드 + Slack 자동 공지까지 확장 | F5: GitLab 커밋 기록, Slack (웹훅 또는 커넥터) | G5: 하→중 | H5: 매주 반복 작업 제거 | I5: 빌드 태그 사이 git log를 Claude에 주고 '기획·사운드가 읽을 공지문' 요청
A6: 5 | B6: A-02, A-03 | C6: 주간회의 준비·진행도 갱신 | D6: 지난주 한 일을 기억과 커밋으로 정리, 진행도 시트 수동 갱신 | E6: 최근 7일 커밋·Slack을 요약해 '한 일 / 할 일 / 이슈' 주간 보고 초안 작성 → 매주 월요일 아침 자동 실행 가능 | F6: GitLab 커밋 기록, 일정표 시트 | G6: 하 | H6: 월요일 준비 시간 단축 | I6: 월요일에 'git log --since=7.days' 결과로 주간 보고 초안 요청
A7: 6 | B7: G-01, G-02 | C7: 다국어 반영·검수 | D7: 다국어 시트 내용을 프로젝트에 넣고 언어별 화면을 직접 확인 | E7: 시트 → 로컬라이징 데이터 변환, 누락 키·포맷 문자열 오류·글자수 초과 후보 사전 검출 | F7: 다국어 시트, 로컬라이징 데이터 구조 | G7: 중 | H7: QA 전 오류 사전 발견 | I7: 다국어 시트 CSV를 주고 누락·이상값 검사 요청
A8: 7 | B8: B-01 ~ B-04 | C8: 신규 프로젝트 세팅 | D8: 매번 비슷한 설정을 수동으로 반복 | E8: 세팅 체크리스트 문서화 + Editor 스크립트로 공통 설정 일괄 적용 | F8: 기존 프로젝트 설정값, 사내 템플릿 | G8: 중 | H8: 세팅 시간 단축, 설정 누락 방지 | I8: 다음 신규 프로젝트 때 세팅 과정을 기록해 체크리스트로 만들기
A9: 8 | B9: H-02, H-03 | C9: 출시 준비 | D9: 스토어 정보·릴리즈 설정을 매번 직접 작성·확인 | E9: 다국어 스토어 설명문 초안, 키즈 앱 정책 체크리스트, 릴리즈 전 설정 점검(디버그 로그·테스트 코드 제거) | F9: 기획 자료, 기존 스토어 정보 | G9: 하 | H9: 작성·점검 시간 단축 | I9: 기존 앱 스토어 설명을 주고 새 앱 설명 초안 요청
A10: 9 | B10: I-01 | C10: 코드 정리 | D10: 출시 후 직접 코드를 훑으며 정리 | E10: 미사용 스크립트·에셋 탐지, 중복 코드 리팩토링 제안 (Claude Code) | F10: Unity 프로젝트 폴더 | G10: 중 | H10: 정리 시간 단축 | I10: Claude Code로 '사용되지 않는 스크립트 찾아줘' 요청
